File: double_output/3360-302.csv
[Measurement conditions]
Sample identification,3360-302
Comment,
Anode material,Co
K-Alpha1 wavelength,1.7890100
K-Alpha2 wavelength,1.7929000
Ratio K-Alpha2/K-Alpha1,0.500
Divergence slit,Fixed,0.76mm
Monochromator used,NO
Generator voltage, 40
Tube current,  8
File date and time,25/3ÔÂ/2025 04:48
Unit cell,
h k l, 0 0 0
Scan axis,Gonio
Scan range,19.998000000,89.999606480
Scan step size,0.0217329
No. of points, 3221
Scan type,CONTINUOUS
Time per step,60.945
[Scan points]
Angle, TimePerStep, Intensity, ESD
20.008866440, 60.945, 4094.0, 63.9844
20.074065080, 60.945, 4018.0, 63.3877
20.139263720, 60.945, 4132.0, 64.2806
20.204462360, 60.945, 4186.0, 64.6993
20.269661000, 60.945, 4141.0, 64.3506
20.334859640, 60.945, 4198.0, 64.7920
20.400058280, 60.945, 4061.0, 63.7260
20.465256920, 60.945, 4168.0, 64.5600
20.530455560, 60.945, 4175.0, 64.6142
20.595654200, 60.945, 4048.0, 63.6239
20.660852840, 60.945, 4179.0, 64.6452
20.726051480, 60.945, 4081.0, 63.8827
20.791250120, 60.945, 4142.0, 64.3584
20.856448760, 60.945, 4132.0, 64.2806
20.921647400, 60.945, 4093.0, 63.9766
20.986846040, 60.945, 4142.0, 64.3584
21.052044680, 60.945, 4157.0, 64.4748
21.117243320, 60.945, 4088.0, 63.9375
21.182441960, 60.945, 4199.0, 64.7997
21.247640600, 60.945, 4116.0, 64.1561
21.312839240, 60.945, 4238.0, 65.0999
21.378037880, 60.945, 4094.0, 63.9844
21.443236520, 60.945, 4132.0, 64.2806
21.508435160, 60.945, 4147.0, 64.3972
21.573633800, 60.945, 4148.0, 64.4050
21.638832440, 60.945, 4037.0, 63.5374
21.704031080, 60.945, 4094.0, 63.9844
21.769229720, 60.945, 4049.0, 63.6318
21.834428360, 60.945, 4066.0, 63.7652
21.899627000, 60.945, 3999.0, 63.2376
21.964825640, 60.945, 4170.0, 64.5755
22.030024280, 60.945, 4181.0, 64.6607
22.095222920, 60.945, 4099.0, 64.0234
22.160421560, 60.945, 4140.0, 64.3428
22.225620200, 60.945, 4160.0, 64.4981
22.290818840, 60.945, 4215.0, 64.9230
22.356017480, 60.945, 4129.0, 64.2573
22.421216120, 60.945, 4160.0, 64.4981
22.486414760, 60.945, 4174.0, 64.6065
22.551613400, 60.945, 4157.0, 64.4748
22.616812040, 60.945, 4210.0, 64.8845
22.682010680, 60.945, 4140.0, 64.3428
22.747209320, 60.945, 4127.0, 64.2417
22.812407960, 60.945, 4244.0, 65.1460
22.877606600, 60.945, 4058.0, 63.7024
22.942805240, 60.945, 4004.0, 63.2772
23.008003880, 60.945, 4048.0, 63.6239
23.073202520, 60.945, 4068.0, 63.7809
23.138401160, 60.945, 4156.0, 64.4670
23.203599800, 60.945, 4290.0, 65.4981
23.268798440, 60.945, 4110.0, 64.1093
23.333997080, 60.945, 4106.0, 64.0781
23.399195720, 60.945, 4068.0, 63.7809
23.464394360, 60.945, 4099.0, 64.0234
23.529593000, 60.945, 4152.0, 64.4360
23.594791640, 60.945, 4104.0, 64.0625
23.659990280, 60.945, 4012.0, 63.3404
23.725188920, 60.945, 4156.0, 64.4670
23.790387560, 60.945, 4093.0, 63.9766
23.855586200, 60.945, 4042.0, 63.5767
23.920784840, 60.945, 4078.0, 63.8592
23.985983480, 60.945, 4106.0, 64.0781
24.051182120, 60.945, 4043.0, 63.5846
24.116380760, 60.945, 4118.0, 64.1716
24.181579400, 60.945, 4062.0, 63.7338
24.246778040, 60.945, 4108.0, 64.0937
24.311976680, 60.945, 4147.0, 64.3972
24.377175320, 60.945, 4064.0, 63.7495
24.442373960, 60.945, 4152.0, 64.4360
24.507572600, 60.945, 4118.0, 64.1716
24.572771240, 60.945, 4208.0, 64.8691
24.637969880, 60.945, 4175.0, 64.6142
24.703168520, 60.945, 4175.0, 64.6142
24.768367160, 60.945, 4121.0, 64.1950
24.833565800, 60.945, 4125.0, 64.2262
24.898764440, 60.945, 3975.0, 63.0476
24.963963080, 60.945, 4012.0, 63.3404
25.029161720, 60.945, 4115.0, 64.1483
25.094360360, 60.945, 4032.0, 63.4980
25.159559000, 60.945, 3990.0, 63.1664
25.224757640, 60.945, 4057.0, 63.6946
25.289956280, 60.945, 4077.0, 63.8514
25.355154920, 60.945, 4105.0, 64.0703
25.420353560, 60.945, 4057.0, 63.6946
25.485552200, 60.945, 4048.0, 63.6239
25.550750840, 60.945, 4207.0, 64.8614
25.615949480, 60.945, 4131.0, 64.2729
25.681148120, 60.945, 4171.0, 64.5833
25.746346760, 60.945, 4177.0, 64.6297
25.811545400, 60.945, 4180.0, 64.6529
25.876744040, 60.945, 4121.0, 64.1950
25.941942680, 60.945, 4076.0, 63.8436
26.007141320, 60.945, 4184.0, 64.6838
26.072339960, 60.945, 4033.0, 63.5059
26.137538600, 60.945, 4143.0, 64.3661
26.202737240, 60.945, 4110.0, 64.1093
26.267935880, 60.945, 4034.0, 63.5138
26.333134520, 60.945, 4060.0, 63.7181
26.398333160, 60.945, 4000.0, 63.2456
26.463531800, 60.945, 4050.0, 63.6396
26.528730440, 60.945, 4127.0, 64.2417
26.593929080, 60.945, 4154.0, 64.4515
26.659127720, 60.945, 3940.0, 62.7694
26.724326360, 60.945, 4079.0, 63.8670
26.789525000, 60.945, 4154.0, 64.4515
26.854723640, 60.945, 4113.0, 64.1327
26.919922280, 60.945, 4116.0, 64.1561
26.985120920, 60.945, 4115.0, 64.1483
27.050319560, 60.945, 4018.0, 63.3877
27.115518200, 60.945, 3976.0, 63.0555
27.180716840, 60.945, 4110.0, 64.1093
27.245915480, 60.945, 4026.0, 63.4508
27.311114120, 60.945, 4143.0, 64.3661
27.376312760, 60.945, 4075.0, 63.8357
27.441511400, 60.945, 4123.0, 64.2106
27.506710040, 60.945, 4004.0, 63.2772
27.571908680, 60.945, 4118.0, 64.1716
27.637107320, 60.945, 4129.0, 64.2573
27.702305960, 60.945, 4093.0, 63.9766
27.767504600, 60.945, 4034.0, 63.5138
27.832703240, 60.945, 4024.0, 63.4350
27.897901880, 60.945, 4202.0, 64.8228
27.963100520, 60.945, 4070.0, 63.7966
28.028299160, 60.945, 3992.0, 63.1823
28.093497800, 60.945, 4086.0, 63.9218
28.158696440, 60.945, 4003.0, 63.2693
28.223895080, 60.945, 4024.0, 63.4350
28.289093720, 60.945, 4147.0, 64.3972
28.354292360, 60.945, 4017.0, 63.3798
28.419491000, 60.945, 4044.0, 63.5925
28.484689640, 60.945, 4183.0, 64.6761
28.549888280, 60.945, 4046.0, 63.6082
28.615086920, 60.945, 4124.0, 64.2184
28.680285560, 60.945, 4063.0, 63.7417
28.745484200, 60.945, 4040.0, 63.5610
28.810682840, 60.945, 4115.0, 64.1483
28.875881480, 60.945, 4118.0, 64.1716
28.941080120, 60.945, 4147.0, 64.3972
29.006278760, 60.945, 4071.0, 63.8044
29.071477400, 60.945, 4102.0, 64.0469
29.136676040, 60.945, 4072.0, 63.8122
29.201874680, 60.945, 4046.0, 63.6082
29.267073320, 60.945, 3978.0, 63.0714
29.332271960, 60.945, 3986.0, 63.1348
29.397470600, 60.945, 3986.0, 63.1348
29.462669240, 60.945, 4040.0, 63.5610
29.527867880, 60.945, 4076.0, 63.8436
29.593066520, 60.945, 3988.0, 63.1506
29.658265160, 60.945, 4080.0, 63.8749
29.723463800, 60.945, 4135.0, 64.3040
29.788662440, 60.945, 4108.0, 64.0937
29.853861080, 60.945, 4127.0, 64.2417
29.919059720, 60.945, 4210.0, 64.8845
29.984258360, 60.945, 3949.0, 62.8411
30.049457000, 60.945, 4002.0, 63.2614
30.114655640, 60.945, 4057.0, 63.6946
30.179854280, 60.945, 4035.0, 63.5216
30.245052920, 60.945, 4096.0, 64.0000
30.310251560, 60.945, 3995.0, 63.2060
30.375450200, 60.945, 4022.0, 63.4192
30.440648840, 60.945, 4005.0, 63.2851
30.505847480, 60.945, 4080.0, 63.8749
30.571046120, 60.945, 4059.0, 63.7103
30.636244760, 60.945, 4063.0, 63.7417
30.701443400, 60.945, 4008.0, 63.3088
30.766642040, 60.945, 3987.0, 63.1427
30.831840680, 60.945, 4045.0, 63.6003
30.897039320, 60.945, 4056.0, 63.6867
30.962237960, 60.945, 4229.0, 65.0308
31.027436600, 60.945, 4228.0, 65.0231
31.092635240, 60.945, 4031.0, 63.4902
31.157833880, 60.945, 3970.0, 63.0079
31.223032520, 60.945, 4069.0, 63.7887
31.288231160, 60.945, 4100.0, 64.0312
31.353429800, 60.945, 4027.0, 63.4586
31.418628440, 60.945, 4030.0, 63.4823
31.483827080, 60.945, 4008.0, 63.3088
31.549025720, 60.945, 4040.0, 63.5610
31.614224360, 60.945, 3973.0, 63.0317
31.679423000, 60.945, 4031.0, 63.4902
31.744621640, 60.945, 4170.0, 64.5755
31.809820280, 60.945, 3935.0, 62.7296
31.875018920, 60.945, 4075.0, 63.8357
31.940217560, 60.945, 4072.0, 63.8122
32.005416200, 60.945, 4058.0, 63.7024
32.070614840, 60.945, 4082.0, 63.8905
32.135813480, 60.945, 4052.0, 63.6553
32.201012120, 60.945, 4062.0, 63.7338
32.266210760, 60.945, 4045.0, 63.6003
32.331409400, 60.945, 4047.0, 63.6160
32.396608040, 60.945, 4091.0, 63.9609
32.461806680, 60.945, 4086.0, 63.9218
32.527005320, 60.945, 4099.0, 64.0234
32.592203960, 60.945, 3945.0, 62.8092
32.657402600, 60.945, 4124.0, 64.2184
32.722601240, 60.945, 3956.0, 62.8967
32.787799880, 60.945, 3905.0, 62.4900
32.852998520, 60.945, 3930.0, 62.6897
32.918197160, 60.945, 4154.0, 64.4515
32.983395800, 60.945, 4148.0, 64.4050
33.048594440, 60.945, 4077.0, 63.8514
33.113793080, 60.945, 4063.0, 63.7417
33.178991720, 60.945, 4020.0, 63.4035
33.244190360, 60.945, 4129.0, 64.2573
33.309389000, 60.945, 4070.0, 63.7966
33.374587640, 60.945, 3997.0, 63.2218
33.439786280, 60.945, 4144.0, 64.3739
33.504984920, 60.945, 4132.0, 64.2806
33.570183560, 60.945, 3987.0, 63.1427
33.635382200, 60.945, 4035.0, 63.5216
33.700580840, 60.945, 4074.0, 63.8279
33.765779480, 60.945, 3969.0, 63.0000
33.830978120, 60.945, 4070.0, 63.7966
33.896176760, 60.945, 4096.0, 64.0000
33.961375400, 60.945, 4024.0, 63.4350
34.026574040, 60.945, 4157.0, 64.4748
34.091772680, 60.945, 4037.0, 63.5374
34.156971320, 60.945, 4076.0, 63.8436
34.222169960, 60.945, 4011.0, 63.3325
34.287368600, 60.945, 4125.0, 64.2262
34.352567240, 60.945, 3864.0, 62.1611
34.417765880, 60.945, 4118.0, 64.1716
34.482964520, 60.945, 3994.0, 63.1981
34.548163160, 60.945, 4015.0, 63.3640
34.613361800, 60.945, 4111.0, 64.1171
34.678560440, 60.945, 4044.0, 63.5925
34.743759080, 60.945, 4212.0, 64.8999
34.808957720, 60.945, 4035.0, 63.5216
34.874156360, 60.945, 4149.0, 64.4127
34.939355000, 60.945, 4163.0, 64.5213
35.004553640, 60.945, 4132.0, 64.2806
35.069752280, 60.945, 4108.0, 64.0937
35.134950920, 60.945, 4008.0, 63.3088
35.200149560, 60.945, 4088.0, 63.9375
35.265348200, 60.945, 4040.0, 63.5610
35.330546840, 60.945, 4125.0, 64.2262
35.395745480, 60.945, 4055.0, 63.6789
35.460944120, 60.945, 4073.0, 63.8201
35.526142760, 60.945, 4065.0, 63.7574
35.591341400, 60.945, 3990.0, 63.1664
35.656540040, 60.945, 4112.0, 64.1249
35.721738680, 60.945, 4095.0, 63.9922
35.786937320, 60.945, 3947.0, 62.8252
35.852135960, 60.945, 4076.0, 63.8436
35.917334600, 60.945, 4085.0, 63.9140
35.982533240, 60.945, 4105.0, 64.0703
36.047731880, 60.945, 3989.0, 63.1585
36.112930520, 60.945, 4060.0, 63.7181
36.178129160, 60.945, 4001.0, 63.2535
36.243327800, 60.945, 4073.0, 63.8201
36.308526440, 60.945, 4014.0, 63.3561
36.373725080, 60.945, 4058.0, 63.7024
36.438923720, 60.945, 3993.0, 63.1902
36.504122360, 60.945, 4069.0, 63.7887
36.569321000, 60.945, 4125.0, 64.2262
36.634519640, 60.945, 4053.0, 63.6632
36.699718280, 60.945, 4105.0, 64.0703
36.764916920, 60.945, 4100.0, 64.0312
36.830115560, 60.945, 4067.0, 63.7730
36.895314200, 60.945, 3979.0, 63.0793
36.960512840, 60.945, 4093.0, 63.9766
37.025711480, 60.945, 4000.0, 63.2456
37.090910120, 60.945, 4138.0, 64.3273
37.156108760, 60.945, 3980.0, 63.0872
37.221307400, 60.945, 4047.0, 63.6160
37.286506040, 60.945, 3906.0, 62.4980
37.351704680, 60.945, 3980.0, 63.0872
37.416903320, 60.945, 4078.0, 63.8592
37.482101960, 60.945, 3982.0, 63.1031
37.547300600, 60.945, 4068.0, 63.7809
37.612499240, 60.945, 3985.0, 63.1269
37.677697880, 60.945, 4063.0, 63.7417
37.742896520, 60.945, 4019.0, 63.3956
37.808095160, 60.945, 4136.0, 64.3117
37.873293800, 60.945, 4015.0, 63.3640
37.938492440, 60.945, 3939.0, 62.7615
38.003691080, 60.945, 4008.0, 63.3088
38.068889720, 60.945, 4003.0, 63.2693
38.134088360, 60.945, 4093.0, 63.9766
38.199287000, 60.945, 4025.0, 63.4429
38.264485640, 60.945, 4005.0, 63.2851
38.329684280, 60.945, 4120.0, 64.1872
38.394882920, 60.945, 3920.0, 62.6099
38.460081560, 60.945, 3970.0, 63.0079
38.525280200, 60.945, 4040.0, 63.5610
38.590478840, 60.945, 3996.0, 63.2139
38.655677480, 60.945, 4004.0, 63.2772
38.720876120, 60.945, 4109.0, 64.1015
38.786074760, 60.945, 4055.0, 63.6789
38.851273400, 60.945, 4246.0, 65.1613
38.916472040, 60.945, 4101.0, 64.0391
38.981670680, 60.945, 4124.0, 64.2184
39.046869320, 60.945, 3988.0, 63.1506
39.112067960, 60.945, 4128.0, 64.2495
39.177266600, 60.945, 3974.0, 63.0397
39.242465240, 60.945, 3989.0, 63.1585
39.307663880, 60.945, 4043.0, 63.5846
39.372862520, 60.945, 4130.0, 64.2651
39.438061160, 60.945, 3962.0, 62.9444
39.503259800, 60.945, 4034.0, 63.5138
39.568458440, 60.945, 4018.0, 63.3877
39.633657080, 60.945, 4059.0, 63.7103
39.698855720, 60.945, 4008.0, 63.3088
39.764054360, 60.945, 3970.0, 63.0079
39.829253000, 60.945, 4004.0, 63.2772
39.894451640, 60.945, 4069.0, 63.7887
39.959650280, 60.945, 3815.0, 61.7657
40.024848920, 60.945, 3905.0, 62.4900
40.090047560, 60.945, 4062.0, 63.7338
40.155246200, 60.945, 3892.0, 62.3859
40.220444840, 60.945, 4099.0, 64.0234
40.285643480, 60.945, 4000.0, 63.2456
40.350842120, 60.945, 4048.0, 63.6239
40.416040760, 60.945, 3886.0, 62.3378
40.481239400, 60.945, 3918.0, 62.5939
40.546438040, 60.945, 4034.0, 63.5138
40.611636680, 60.945, 3993.0, 63.1902
40.676835320, 60.945, 3957.0, 62.9047
40.742033960, 60.945, 4024.0, 63.4350
40.807232600, 60.945, 4032.0, 63.4980
40.872431240, 60.945, 4057.0, 63.6946
40.937629880, 60.945, 4001.0, 63.2535
41.002828520, 60.945, 4122.0, 64.2028
41.068027160, 60.945, 3929.0, 62.6817
41.133225800, 60.945, 4164.0, 64.5291
41.198424440, 60.945, 3971.0, 63.0159
41.263623080, 60.945, 4087.0, 63.9296
41.328821720, 60.945, 4000.0, 63.2456
41.394020360, 60.945, 4011.0, 63.3325
41.459219000, 60.945, 4251.0, 65.1997
41.524417640, 60.945, 4148.0, 64.4050
41.589616280, 60.945, 4277.0, 65.3988
41.654814920, 60.945, 4015.0, 63.3640
41.720013560, 60.945, 3989.0, 63.1585
41.785212200, 60.945, 4199.0, 64.7997
41.850410840, 60.945, 4077.0, 63.8514
41.915609480, 60.945, 4119.0, 64.1794
41.980808120, 60.945, 4065.0, 63.7574
42.046006760, 60.945, 3950.0, 62.8490
42.111205400, 60.945, 4079.0, 63.8670
42.176404040, 60.945, 3931.0, 62.6977
42.241602680, 60.945, 4013.0, 63.3482
42.306801320, 60.945, 3994.0, 63.1981
42.371999960, 60.945, 3963.0, 62.9524
42.437198600, 60.945, 4070.0, 63.7966
42.502397240, 60.945, 3936.0, 62.7375
42.567595880, 60.945, 4048.0, 63.6239
42.632794520, 60.945, 4005.0, 63.2851
42.697993160, 60.945, 3951.0, 62.8570
42.763191800, 60.945, 3952.0, 62.8649
42.828390440, 60.945, 3956.0, 62.8967
42.893589080, 60.945, 4105.0, 64.0703
42.958787720, 60.945, 4030.0, 63.4823
43.023986360, 60.945, 3988.0, 63.1506
43.089185000, 60.945, 3985.0, 63.1269
43.154383640, 60.945, 4036.0, 63.5295
43.219582280, 60.945, 4008.0, 63.3088
43.284780920, 60.945, 3914.0, 62.5620
43.349979560, 60.945, 4126.0, 64.2339
43.415178200, 60.945, 4038.0, 63.5453
43.480376840, 60.945, 3860.0, 62.1289
43.545575480, 60.945, 4068.0, 63.7809
43.610774120, 60.945, 4095.0, 63.9922
43.675972760, 60.945, 4002.0, 63.2614
43.741171400, 60.945, 3959.0, 62.9206
43.806370040, 60.945, 3873.0, 62.2334
43.871568680, 60.945, 4107.0, 64.0859
43.936767320, 60.945, 3998.0, 63.2297
44.001965960, 60.945, 4047.0, 63.6160
44.067164600, 60.945, 4007.0, 63.3009
44.132363240, 60.945, 4015.0, 63.3640
44.197561880, 60.945, 4000.0, 63.2456
44.262760520, 60.945, 3920.0, 62.6099
44.327959160, 60.945, 4093.0, 63.9766
44.393157800, 60.945, 4029.0, 63.4744
44.458356440, 60.945, 4031.0, 63.4902
44.523555080, 60.945, 4058.0, 63.7024
44.588753720, 60.945, 3958.0, 62.9126
44.653952360, 60.945, 4011.0, 63.3325
44.719151000, 60.945, 4060.0, 63.7181
44.784349640, 60.945, 4083.0, 63.8984
44.849548280, 60.945, 4099.0, 64.0234
44.914746920, 60.945, 3980.0, 63.0872
44.979945560, 60.945, 4092.0, 63.9687
45.045144200, 60.945, 4069.0, 63.7887
45.110342840, 60.945, 4034.0, 63.5138
45.175541480, 60.945, 4074.0, 63.8279
45.240740120, 60.945, 3991.0, 63.1744
45.305938760, 60.945, 4063.0, 63.7417
45.371137400, 60.945, 3865.0, 62.1691
45.436336040, 60.945, 4032.0, 63.4980
45.501534680, 60.945, 4023.0, 63.4271
45.566733320, 60.945, 3969.0, 63.0000
45.631931960, 60.945, 4092.0, 63.9687
45.697130600, 60.945, 4039.0, 63.5531
45.762329240, 60.945, 4009.0, 63.3167
45.827527880, 60.945, 4095.0, 63.9922
45.892726520, 60.945, 3999.0, 63.2376
45.957925160, 60.945, 4008.0, 63.3088
46.023123800, 60.945, 4078.0, 63.8592
46.088322440, 60.945, 3993.0, 63.1902
46.153521080, 60.945, 4072.0, 63.8122
46.218719720, 60.945, 4087.0, 63.9296
46.283918360, 60.945, 4173.0, 64.5988
46.349117000, 60.945, 4110.0, 64.1093
46.414315640, 60.945, 4089.0, 63.9453
46.479514280, 60.945, 4115.0, 64.1483
46.544712920, 60.945, 4010.0, 63.3246
46.609911560, 60.945, 3950.0, 62.8490
46.675110200, 60.945, 4007.0, 63.3009
46.740308840, 60.945, 4072.0, 63.8122
46.805507480, 60.945, 4143.0, 64.3661
46.870706120, 60.945, 4104.0, 64.0625
46.935904760, 60.945, 3981.0, 63.0952
47.001103400, 60.945, 4077.0, 63.8514
47.066302040, 60.945, 4076.0, 63.8436
47.131500680, 60.945, 3975.0, 63.0476
47.196699320, 60.945, 4009.0, 63.3167
47.261897960, 60.945, 4028.0, 63.4665
47.327096600, 60.945, 4025.0, 63.4429
47.392295240, 60.945, 4072.0, 63.8122
47.457493880, 60.945, 4102.0, 64.0469
47.522692520, 60.945, 4124.0, 64.2184
47.587891160, 60.945, 4044.0, 63.5925
47.653089800, 60.945, 4051.0, 63.6475
47.718288440, 60.945, 4014.0, 63.3561
47.783487080, 60.945, 4104.0, 64.0625
47.848685720, 60.945, 4191.0, 64.7379
47.913884360, 60.945, 4215.0, 64.9230
47.979083000, 60.945, 4052.0, 63.6553
48.044281640, 60.945, 4166.0, 64.5446
48.109480280, 60.945, 4128.0, 64.2495
48.174678920, 60.945, 4072.0, 63.8122
48.239877560, 60.945, 4195.0, 64.7688
48.305076200, 60.945, 4047.0, 63.6160
48.370274840, 60.945, 4162.0, 64.5136
48.435473480, 60.945, 4112.0, 64.1249
48.500672120, 60.945, 3960.0, 62.9285
48.565870760, 60.945, 4163.0, 64.5213
48.631069400, 60.945, 4039.0, 63.5531
48.696268040, 60.945, 4037.0, 63.5374
48.761466680, 60.945, 4159.0, 64.4903
48.826665320, 60.945, 4123.0, 64.2106
48.891863960, 60.945, 4074.0, 63.8279
48.957062600, 60.945, 4094.0, 63.9844
49.022261240, 60.945, 4083.0, 63.8984
49.087459880, 60.945, 4020.0, 63.4035
49.152658520, 60.945, 4081.0, 63.8827
49.217857160, 60.945, 4107.0, 64.0859
49.283055800, 60.945, 4128.0, 64.2495
49.348254440, 60.945, 4197.0, 64.7843
49.413453080, 60.945, 4008.0, 63.3088
49.478651720, 60.945, 4134.0, 64.2962
49.543850360, 60.945, 4133.0, 64.2884
49.609049000, 60.945, 4160.0, 64.4981
49.674247640, 60.945, 4017.0, 63.3798
49.739446280, 60.945, 4064.0, 63.7495
49.804644920, 60.945, 4127.0, 64.2417
49.869843560, 60.945, 4263.0, 65.2917
49.935042200, 60.945, 4186.0, 64.6993
50.000240840, 60.945, 4210.0, 64.8845
50.065439480, 60.945, 4112.0, 64.1249
50.130638120, 60.945, 4129.0, 64.2573
50.195836760, 60.945, 4285.0, 65.4599
50.261035400, 60.945, 4212.0, 64.8999
50.326234040, 60.945, 4209.0, 64.8768
50.391432680, 60.945, 4252.0, 65.2074
50.456631320, 60.945, 4260.0, 65.2687
50.521829960, 60.945, 4245.0, 65.1537
50.587028600, 60.945, 4292.0, 65.5134
50.652227240, 60.945, 4242.0, 65.1306
50.717425880, 60.945, 4190.0, 64.7302
50.782624520, 60.945, 4355.0, 65.9924
50.847823160, 60.945, 4301.0, 65.5820
50.913021800, 60.945, 4294.0, 65.5286
50.978220440, 60.945, 4284.0, 65.4523
51.043419080, 60.945, 4229.0, 65.0308
51.108617720, 60.945, 4374.0, 66.1362
51.173816360, 60.945, 4548.0, 67.4389
51.239015000, 60.945, 4414.0, 66.4379
51.304213640, 60.945, 4524.0, 67.2607
51.369412280, 60.945, 4545.0, 67.4166
51.434610920, 60.945, 4561.0, 67.5352
51.499809560, 60.945, 4717.0, 68.6804
51.565008200, 60.945, 4883.0, 69.8785
51.630206840, 60.945, 4810.0, 69.3542
51.695405480, 60.945, 5089.0, 71.3372
51.760604120, 60.945, 5252.0, 72.4707
51.825802760, 60.945, 5588.0, 74.7529
51.891001400, 60.945, 6153.0, 78.4411
51.956200040, 60.945, 6849.0, 82.7587
52.021398680, 60.945, 7645.0, 87.4357
52.086597320, 60.945, 9125.0, 95.5249
52.151795960, 60.945, 10779.0, 103.8220
52.216994600, 60.945, 13256.0, 115.1347
52.282193240, 60.945, 16165.0, 127.1417
52.347391880, 60.945, 19437.0, 139.4166
52.412590520, 60.945, 22230.0, 149.0973
52.477789160, 60.945, 24259.0, 155.7530
52.542987800, 60.945, 24909.0, 157.8259
52.608186440, 60.945, 23808.0, 154.2984
52.673385080, 60.945, 21630.0, 147.0714
52.738583720, 60.945, 18833.0, 137.2334
52.803782360, 60.945, 15882.0, 126.0238
52.868981000, 60.945, 13227.0, 115.0087
52.934179640, 60.945, 11289.0, 106.2497
52.999378280, 60.945, 9681.0, 98.3921
53.064576920, 60.945, 8509.0, 92.2442
53.129775560, 60.945, 7462.0, 86.3829
53.194974200, 60.945, 6716.0, 81.9512
53.260172840, 60.945, 6221.0, 78.8733
53.325371480, 60.945, 5869.0, 76.6094
53.390570120, 60.945, 5482.0, 74.0405
53.455768760, 60.945, 5250.0, 72.4569
53.520967400, 60.945, 4986.0, 70.6116
53.586166040, 60.945, 4926.0, 70.1855
53.651364680, 60.945, 4719.0, 68.6950
53.716563320, 60.945, 4663.0, 68.2862
53.781761960, 60.945, 4638.0, 68.1029
53.846960600, 60.945, 4575.0, 67.6387
53.912159240, 60.945, 4447.0, 66.6858
53.977357880, 60.945, 4544.0, 67.4092
54.042556520, 60.945, 4449.0, 66.7008
54.107755160, 60.945, 4475.0, 66.8954
54.172953800, 60.945, 4305.0, 65.6125
54.238152440, 60.945, 4494.0, 67.0373
54.303351080, 60.945, 4323.0, 65.7495
54.368549720, 60.945, 4391.0, 66.2646
54.433748360, 60.945, 4450.0, 66.7083
54.498947000, 60.945, 4390.0, 66.2571
54.564145640, 60.945, 4321.0, 65.7343
54.629344280, 60.945, 4312.0, 65.6658
54.694542920, 60.945, 4369.0, 66.0984
54.759741560, 60.945, 4227.0, 65.0154
54.824940200, 60.945, 4351.0, 65.9621
54.890138840, 60.945, 4233.0, 65.0615
54.955337480, 60.945, 4183.0, 64.6761
55.020536120, 60.945, 4316.0, 65.6963
55.085734760, 60.945, 4351.0, 65.9621
55.150933400, 60.945, 4285.0, 65.4599
55.216132040, 60.945, 4280.0, 65.4217
55.281330680, 60.945, 4178.0, 64.6375
55.346529320, 60.945, 4220.0, 64.9615
55.411727960, 60.945, 4313.0, 65.6734
55.476926600, 60.945, 4215.0, 64.9230
55.542125240, 60.945, 4240.0, 65.1153
55.607323880, 60.945, 4282.0, 65.4370
55.672522520, 60.945, 4271.0, 65.3529
55.737721160, 60.945, 4323.0, 65.7495
55.802919800, 60.945, 4338.0, 65.8635
55.868118440, 60.945, 4342.0, 65.8939
55.933317080, 60.945, 4293.0, 65.5210
55.998515720, 60.945, 4273.0, 65.3682
56.063714360, 60.945, 4348.0, 65.9394
56.128913000, 60.945, 4247.0, 65.1690
56.194111640, 60.945, 4359.0, 66.0227
56.259310280, 60.945, 4222.0, 64.9769
56.324508920, 60.945, 4249.0, 65.1844
56.389707560, 60.945, 4302.0, 65.5896
56.454906200, 60.945, 4354.0, 65.9848
56.520104840, 60.945, 4342.0, 65.8939
56.585303480, 60.945, 4264.0, 65.2993
56.650502120, 60.945, 4259.0, 65.2610
56.715700760, 60.945, 4206.0, 64.8537
56.780899400, 60.945, 4344.0, 65.9090
56.846098040, 60.945, 4195.0, 64.7688
56.911296680, 60.945, 4299.0, 65.5668
56.976495320, 60.945, 4172.0, 64.5910
57.041693960, 60.945, 4264.0, 65.2993
57.106892600, 60.945, 4244.0, 65.1460
57.172091240, 60.945, 4375.0, 66.1438
57.237289880, 60.945, 4354.0, 65.9848
57.302488520, 60.945, 4337.0, 65.8559
57.367687160, 60.945, 4283.0, 65.4446
57.432885800, 60.945, 4288.0, 65.4828
57.498084440, 60.945, 4185.0, 64.6916
57.563283080, 60.945, 4171.0, 64.5833
57.628481720, 60.945, 4235.0, 65.0769
57.693680360, 60.945, 4290.0, 65.4981
57.758879000, 60.945, 4276.0, 65.3911
57.824077640, 60.945, 4253.0, 65.2150
57.889276280, 60.945, 4212.0, 64.8999
57.954474920, 60.945, 4321.0, 65.7343
58.019673560, 60.945, 4277.0, 65.3988
58.084872200, 60.945, 4248.0, 65.1767
58.150070840, 60.945, 4208.0, 64.8691
58.215269480, 60.945, 4245.0, 65.1537
58.280468120, 60.945, 4295.0, 65.5362
58.345666760, 60.945, 4317.0, 65.7039
58.410865400, 60.945, 4346.0, 65.9242
58.476064040, 60.945, 4335.0, 65.8407
58.541262680, 60.945, 4312.0, 65.6658
58.606461320, 60.945, 4070.0, 63.7966
58.671659960, 60.945, 4222.0, 64.9769
58.736858600, 60.945, 4220.0, 64.9615
58.802057240, 60.945, 4197.0, 64.7843
58.867255880, 60.945, 4384.0, 66.2118
58.932454520, 60.945, 4336.0, 65.8483
58.997653160, 60.945, 4281.0, 65.4294
59.062851800, 60.945, 4303.0, 65.5973
59.128050440, 60.945, 4168.0, 64.5600
59.193249080, 60.945, 4253.0, 65.2150
59.258447720, 60.945, 4300.0, 65.5744
59.323646360, 60.945, 4309.0, 65.6430
59.388845000, 60.945, 4301.0, 65.5820
59.454043640, 60.945, 4247.0, 65.1690
59.519242280, 60.945, 4313.0, 65.6734
59.584440920, 60.945, 4210.0, 64.8845
59.649639560, 60.945, 4343.0, 65.9014
59.714838200, 60.945, 4195.0, 64.7688
59.780036840, 60.945, 4316.0, 65.6963
59.845235480, 60.945, 4365.0, 66.0681
59.910434120, 60.945, 4335.0, 65.8407
59.975632760, 60.945, 4271.0, 65.3529
60.040831400, 60.945, 4279.0, 65.4141
60.106030040, 60.945, 4215.0, 64.9230
60.171228680, 60.945, 4233.0, 65.0615
60.236427320, 60.945, 4265.0, 65.3070
60.301625960, 60.945, 4327.0, 65.7799
60.366824600, 60.945, 4336.0, 65.8483
60.432023240, 60.945, 4247.0, 65.1690
60.497221880, 60.945, 4415.0, 66.4455
60.562420520, 60.945, 4224.0, 64.9923
60.627619160, 60.945, 4366.0, 66.0757
60.692817800, 60.945, 4229.0, 65.0308
60.758016440, 60.945, 4389.0, 66.2495
60.823215080, 60.945, 4343.0, 65.9014
60.888413720, 60.945, 4311.0, 65.6582
60.953612360, 60.945, 4445.0, 66.6708
61.018811000, 60.945, 4252.0, 65.2074
61.084009640, 60.945, 4341.0, 65.8863
61.149208280, 60.945, 4342.0, 65.8939
61.214406920, 60.945, 4285.0, 65.4599
61.279605560, 60.945, 4262.0, 65.2840
61.344804200, 60.945, 4384.0, 66.2118
61.410002840, 60.945, 4255.0, 65.2304
61.475201480, 60.945, 4181.0, 64.6607
61.540400120, 60.945, 4171.0, 64.5833
61.605598760, 60.945, 4269.0, 65.3376
61.670797400, 60.945, 4233.0, 65.0615
61.735996040, 60.945, 4292.0, 65.5134
61.801194680, 60.945, 4318.0, 65.7115
61.866393320, 60.945, 4426.0, 66.5282
61.931591960, 60.945, 4252.0, 65.2074
61.996790600, 60.945, 4262.0, 65.2840
62.061989240, 60.945, 4291.0, 65.5057
62.127187880, 60.945, 4190.0, 64.7302
62.192386520, 60.945, 4331.0, 65.8103
62.257585160, 60.945, 4324.0, 65.7571
62.322783800, 60.945, 4399.0, 66.3250
62.387982440, 60.945, 4188.0, 64.7148
62.453181080, 60.945, 4377.0, 66.1589
62.518379720, 60.945, 4291.0, 65.5057
62.583578360, 60.945, 4278.0, 65.4064
62.648777000, 60.945, 4214.0, 64.9153
62.713975640, 60.945, 4212.0, 64.8999
62.779174280, 60.945, 4317.0, 65.7039
62.844372920, 60.945, 4175.0, 64.6142
62.909571560, 60.945, 4180.0, 64.6529
62.974770200, 60.945, 4294.0, 65.5286
63.039968840, 60.945, 4352.0, 65.9697
63.105167480, 60.945, 4344.0, 65.9090
63.170366120, 60.945, 4250.0, 65.1920
63.235564760, 60.945, 4257.0, 65.2457
63.300763400, 60.945, 4397.0, 66.3099
63.365962040, 60.945, 4287.0, 65.4752
63.431160680, 60.945, 4402.0, 66.3476
63.496359320, 60.945, 4224.0, 64.9923
63.561557960, 60.945, 4279.0, 65.4141
63.626756600, 60.945, 4230.0, 65.0385
63.691955240, 60.945, 4407.0, 66.3852
63.757153880, 60.945, 4486.0, 66.9776
63.822352520, 60.945, 4335.0, 65.8407
63.887551160, 60.945, 4178.0, 64.6375
63.952749800, 60.945, 4316.0, 65.6963
64.017948440, 60.945, 4119.0, 64.1794
64.083147080, 60.945, 4307.0, 65.6277
64.148345720, 60.945, 4260.0, 65.2687
64.213544360, 60.945, 4369.0, 66.0984
64.278743000, 60.945, 4245.0, 65.1537
64.343941640, 60.945, 4237.0, 65.0922
64.409140280, 60.945, 4377.0, 66.1589
64.474338920, 60.945, 4343.0, 65.9014
64.539537560, 60.945, 4293.0, 65.5210
64.604736200, 60.945, 4333.0, 65.8255
64.669934840, 60.945, 4289.0, 65.4905
64.735133480, 60.945, 4453.0, 66.7308
64.800332120, 60.945, 4322.0, 65.7419
64.865530760, 60.945, 4252.0, 65.2074
64.930729400, 60.945, 4375.0, 66.1438
64.995928040, 60.945, 4225.0, 65.0000
65.061126680, 60.945, 4335.0, 65.8407
65.126325320, 60.945, 4301.0, 65.5820
65.191523960, 60.945, 4337.0, 65.8559
65.256722600, 60.945, 4295.0, 65.5362
65.321921240, 60.945, 4259.0, 65.2610
65.387119880, 60.945, 4270.0, 65.3452
65.452318520, 60.945, 4223.0, 64.9846
65.517517160, 60.945, 4386.0, 66.2269
65.582715800, 60.945, 4291.0, 65.5057
65.647914440, 60.945, 4387.0, 66.2344
65.713113080, 60.945, 4443.0, 66.6558
65.778311720, 60.945, 4269.0, 65.3376
65.843510360, 60.945, 4279.0, 65.4141
65.908709000, 60.945, 4289.0, 65.4905
65.973907640, 60.945, 4282.0, 65.4370
66.039106280, 60.945, 4213.0, 64.9076
66.104304920, 60.945, 4310.0, 65.6506
66.169503560, 60.945, 4192.0, 64.7457
66.234702200, 60.945, 4390.0, 66.2571
66.299900840, 60.945, 4270.0, 65.3452
66.365099480, 60.945, 4216.0, 64.9307
66.430298120, 60.945, 4305.0, 65.6125
66.495496760, 60.945, 4317.0, 65.7039
66.560695400, 60.945, 4268.0, 65.3299
66.625894040, 60.945, 4167.0, 64.5523
66.691092680, 60.945, 4204.0, 64.8383
66.756291320, 60.945, 4258.0, 65.2534
66.821489960, 60.945, 4359.0, 66.0227
66.886688600, 60.945, 4299.0, 65.5668
66.951887240, 60.945, 4318.0, 65.7115
67.017085880, 60.945, 4350.0, 65.9545
67.082284520, 60.945, 4390.0, 66.2571
67.147483160, 60.945, 4254.0, 65.2227
67.212681800, 60.945, 4361.0, 66.0379
67.277880440, 60.945, 4401.0, 66.3400
67.343079080, 60.945, 4322.0, 65.7419
67.408277720, 60.945, 4188.0, 64.7148
67.473476360, 60.945, 4374.0, 66.1362
67.538675000, 60.945, 4345.0, 65.9166
67.603873640, 60.945, 4480.0, 66.9328
67.669072280, 60.945, 4220.0, 64.9615
67.734270920, 60.945, 4303.0, 65.5973
67.799469560, 60.945, 4283.0, 65.4446
67.864668200, 60.945, 4301.0, 65.5820
67.929866840, 60.945, 4412.0, 66.4229
67.995065480, 60.945, 4354.0, 65.9848
68.060264120, 60.945, 4200.0, 64.8074
68.125462760, 60.945, 4323.0, 65.7495
68.190661400, 60.945, 4256.0, 65.2380
68.255860040, 60.945, 4262.0, 65.2840
68.321058680, 60.945, 4373.0, 66.1287
68.386257320, 60.945, 4252.0, 65.2074
68.451455960, 60.945, 4240.0, 65.1153
68.516654600, 60.945, 4312.0, 65.6658
68.581853240, 60.945, 4300.0, 65.5744
68.647051880, 60.945, 4252.0, 65.2074
68.712250520, 60.945, 4218.0, 64.9461
68.777449160, 60.945, 4189.0, 64.7225
68.842647800, 60.945, 4234.0, 65.0692
68.907846440, 60.945, 4402.0, 66.3476
68.973045080, 60.945, 4242.0, 65.1306
69.038243720, 60.945, 4397.0, 66.3099
69.103442360, 60.945, 4348.0, 65.9394
69.168641000, 60.945, 4338.0, 65.8635
69.233839640, 60.945, 4209.0, 64.8768
69.299038280, 60.945, 4233.0, 65.0615
69.364236920, 60.945, 4239.0, 65.1076
69.429435560, 60.945, 4309.0, 65.6430
69.494634200, 60.945, 4339.0, 65.8711
69.559832840, 60.945, 4259.0, 65.2610
69.625031480, 60.945, 4141.0, 64.3506
69.690230120, 60.945, 4202.0, 64.8228
69.755428760, 60.945, 4393.0, 66.2797
69.820627400, 60.945, 4269.0, 65.3376
69.885826040, 60.945, 4272.0, 65.3605
69.951024680, 60.945, 4443.0, 66.6558
70.016223320, 60.945, 4289.0, 65.4905
70.081421960, 60.945, 4343.0, 65.9014
70.146620600, 60.945, 4417.0, 66.4605
70.211819240, 60.945, 4183.0, 64.6761
70.277017880, 60.945, 4187.0, 64.7070
70.342216520, 60.945, 4172.0, 64.5910
70.407415160, 60.945, 4194.0, 64.7611
70.472613800, 60.945, 4316.0, 65.6963
70.537812440, 60.945, 4512.0, 67.1714
70.603011080, 60.945, 4393.0, 66.2797
70.668209720, 60.945, 4380.0, 66.1816
70.733408360, 60.945, 4351.0, 65.9621
70.798607000, 60.945, 4313.0, 65.6734
70.863805640, 60.945, 4295.0, 65.5362
70.929004280, 60.945, 4261.0, 65.2763
70.994202920, 60.945, 4307.0, 65.6277
71.059401560, 60.945, 4365.0, 66.0681
71.124600200, 60.945, 4441.0, 66.6408
71.189798840, 60.945, 4353.0, 65.9773
71.254997480, 60.945, 4251.0, 65.1997
71.320196120, 60.945, 4387.0, 66.2344
71.385394760, 60.945, 4296.0, 65.5439
71.450593400, 60.945, 4451.0, 66.7158
71.515792040, 60.945, 4321.0, 65.7343
71.580990680, 60.945, 4363.0, 66.0530
71.646189320, 60.945, 4350.0, 65.9545
71.711387960, 60.945, 4272.0, 65.3605
71.776586600, 60.945, 4465.0, 66.8207
71.841785240, 60.945, 4224.0, 64.9923
71.906983880, 60.945, 4323.0, 65.7495
71.972182520, 60.945, 4347.0, 65.9318
72.037381160, 60.945, 4272.0, 65.3605
72.102579800, 60.945, 4408.0, 66.3928
72.167778440, 60.945, 4360.0, 66.0303
72.232977080, 60.945, 4387.0, 66.2344
72.298175720, 60.945, 4391.0, 66.2646
72.363374360, 60.945, 4353.0, 65.9773
72.428573000, 60.945, 4337.0, 65.8559
72.493771640, 60.945, 4401.0, 66.3400
72.558970280, 60.945, 4430.0, 66.5582
72.624168920, 60.945, 4217.0, 64.9384
72.689367560, 60.945, 4252.0, 65.2074
72.754566200, 60.945, 4422.0, 66.4981
72.819764840, 60.945, 4425.0, 66.5207
72.884963480, 60.945, 4445.0, 66.6708
72.950162120, 60.945, 4514.0, 67.1863
73.015360760, 60.945, 4434.0, 66.5883
73.080559400, 60.945, 4333.0, 65.8255
73.145758040, 60.945, 4387.0, 66.2344
73.210956680, 60.945, 4387.0, 66.2344
73.276155320, 60.945, 4348.0, 65.9394
73.341353960, 60.945, 4346.0, 65.9242
73.406552600, 60.945, 4281.0, 65.4294
73.471751240, 60.945, 4430.0, 66.5582
73.536949880, 60.945, 4386.0, 66.2269
73.602148520, 60.945, 4355.0, 65.9924
73.667347160, 60.945, 4387.0, 66.2344
73.732545800, 60.945, 4355.0, 65.9924
73.797744440, 60.945, 4521.0, 67.2384
73.862943080, 60.945, 4335.0, 65.8407
73.928141720, 60.945, 4552.0, 67.4685
73.993340360, 60.945, 4436.0, 66.6033
74.058539000, 60.945, 4475.0, 66.8954
74.123737640, 60.945, 4467.0, 66.8356
74.188936280, 60.945, 4433.0, 66.5808
74.254134920, 60.945, 4574.0, 67.6314
74.319333560, 60.945, 4610.0, 67.8970
74.384532200, 60.945, 4351.0, 65.9621
74.449730840, 60.945, 4425.0, 66.5207
74.514929480, 60.945, 4578.0, 67.6609
74.580128120, 60.945, 4466.0, 66.8281
74.645326760, 60.945, 4495.0, 67.0448
74.710525400, 60.945, 4409.0, 66.4003
74.775724040, 60.945, 4500.0, 67.0820
74.840922680, 60.945, 4484.0, 66.9627
74.906121320, 60.945, 4518.0, 67.2161
74.971319960, 60.945, 4363.0, 66.0530
75.036518600, 60.945, 4407.0, 66.3852
75.101717240, 60.945, 4463.0, 66.8057
75.166915880, 60.945, 4476.0, 66.9029
75.232114520, 60.945, 4488.0, 66.9925
75.297313160, 60.945, 4530.0, 67.3053
75.362511800, 60.945, 4399.0, 66.3250
75.427710440, 60.945, 4508.0, 67.1416
75.492909080, 60.945, 4611.0, 67.9043
75.558107720, 60.945, 4474.0, 66.8880
75.623306360, 60.945, 4637.0, 68.0955
75.688505000, 60.945, 4729.0, 68.7677
75.753703640, 60.945, 4622.0, 67.9853
75.818902280, 60.945, 4649.0, 68.1836
75.884100920, 60.945, 4662.0, 68.2788
75.949299560, 60.945, 4711.0, 68.6367
76.014498200, 60.945, 4654.0, 68.2202
76.079696840, 60.945, 4843.0, 69.5917
76.144895480, 60.945, 4918.0, 70.1285
76.210094120, 60.945, 5022.0, 70.8661
76.275292760, 60.945, 5159.0, 71.8262
76.340491400, 60.945, 5140.0, 71.6938
76.405690040, 60.945, 5369.0, 73.2735
76.470888680, 60.945, 5497.0, 74.1418
76.536087320, 60.945, 5656.0, 75.2064
76.601285960, 60.945, 5780.0, 76.0263
76.666484600, 60.945, 6029.0, 77.6466
76.731683240, 60.945, 6128.0, 78.2815
76.796881880, 60.945, 6410.0, 80.0625
76.862080520, 60.945, 6664.0, 81.6333
76.927279160, 60.945, 6916.0, 83.1625
76.992477800, 60.945, 7143.0, 84.5163
77.057676440, 60.945, 7361.0, 85.7963
77.122875080, 60.945, 7620.0, 87.2926
77.188073720, 60.945, 7922.0, 89.0056
77.253272360, 60.945, 8267.0, 90.9230
77.318471000, 60.945, 8177.0, 90.4268
77.383669640, 60.945, 8376.0, 91.5205
77.448868280, 60.945, 8355.0, 91.4057
77.514066920, 60.945, 8115.0, 90.0833
77.579265560, 60.945, 8078.0, 89.8777
77.644464200, 60.945, 7843.0, 88.5607
77.709662840, 60.945, 7479.0, 86.4812
77.774861480, 60.945, 7406.0, 86.0581
77.840060120, 60.945, 7033.0, 83.8630
77.905258760, 60.945, 6804.0, 82.4864
77.970457400, 60.945, 6603.0, 81.2588
78.035656040, 60.945, 6376.0, 79.8499
78.100854680, 60.945, 6163.0, 78.5048
78.166053320, 60.945, 5904.0, 76.8375
78.231251960, 60.945, 5619.0, 74.9600
78.296450600, 60.945, 5511.0, 74.2361
78.361649240, 60.945, 5465.0, 73.9256
78.426847880, 60.945, 5262.0, 72.5396
78.492046520, 60.945, 5232.0, 72.3326
78.557245160, 60.945, 4971.0, 70.5053
78.622443800, 60.945, 5025.0, 70.8872
78.687642440, 60.945, 4971.0, 70.5053
78.752841080, 60.945, 4799.0, 69.2748
78.818039720, 60.945, 4816.0, 69.3974
78.883238360, 60.945, 4759.0, 68.9855
78.948437000, 60.945, 4661.0, 68.2715
79.013635640, 60.945, 4698.0, 68.5420
79.078834280, 60.945, 4728.0, 68.7605
79.144032920, 60.945, 4546.0, 67.4240
79.209231560, 60.945, 4676.0, 68.3813
79.274430200, 60.945, 4677.0, 68.3886
79.339628840, 60.945, 4558.0, 67.5130
79.404827480, 60.945, 4699.0, 68.5493
79.470026120, 60.945, 4423.0, 66.5056
79.535224760, 60.945, 4585.0, 67.7126
79.600423400, 60.945, 4578.0, 67.6609
79.665622040, 60.945, 4509.0, 67.1491
79.730820680, 60.945, 4481.0, 66.9403
79.796019320, 60.945, 4423.0, 66.5056
79.861217960, 60.945, 4503.0, 67.1044
79.926416600, 60.945, 4390.0, 66.2571
79.991615240, 60.945, 4511.0, 67.1640
80.056813880, 60.945, 4431.0, 66.5658
80.122012520, 60.945, 4544.0, 67.4092
80.187211160, 60.945, 4461.0, 66.7907
80.252409800, 60.945, 4509.0, 67.1491
80.317608440, 60.945, 4549.0, 67.4463
80.382807080, 60.945, 4467.0, 66.8356
80.448005720, 60.945, 4584.0, 67.7052
80.513204360, 60.945, 4533.0, 67.3276
80.578403000, 60.945, 4412.0, 66.4229
80.643601640, 60.945, 4425.0, 66.5207
80.708800280, 60.945, 4535.0, 67.3424
80.773998920, 60.945, 4456.0, 66.7533
80.839197560, 60.945, 4522.0, 67.2458
80.904396200, 60.945, 4428.0, 66.5432
80.969594840, 60.945, 4486.0, 66.9776
81.034793480, 60.945, 4495.0, 67.0448
81.099992120, 60.945, 4421.0, 66.4906
81.165190760, 60.945, 4575.0, 67.6387
81.230389400, 60.945, 4441.0, 66.6408
81.295588040, 60.945, 4593.0, 67.7717
81.360786680, 60.945, 4467.0, 66.8356
81.425985320, 60.945, 4389.0, 66.2495
81.491183960, 60.945, 4465.0, 66.8207
81.556382600, 60.945, 4336.0, 65.8483
81.621581240, 60.945, 4410.0, 66.4078
81.686779880, 60.945, 4438.0, 66.6183
81.751978520, 60.945, 4476.0, 66.9029
81.817177160, 60.945, 4573.0, 67.6240
81.882375800, 60.945, 4472.0, 66.8730
81.947574440, 60.945, 4509.0, 67.1491
82.012773080, 60.945, 4439.0, 66.6258
82.077971720, 60.945, 4428.0, 66.5432
82.143170360, 60.945, 4551.0, 67.4611
82.208369000, 60.945, 4500.0, 67.0820
82.273567640, 60.945, 4516.0, 67.2012
82.338766280, 60.945, 4534.0, 67.3350
82.403964920, 60.945, 4528.0, 67.2904
82.469163560, 60.945, 4445.0, 66.6708
82.534362200, 60.945, 4417.0, 66.4605
82.599560840, 60.945, 4470.0, 66.8581
82.664759480, 60.945, 4363.0, 66.0530
82.729958120, 60.945, 4410.0, 66.4078
82.795156760, 60.945, 4474.0, 66.8880
82.860355400, 60.945, 4421.0, 66.4906
82.925554040, 60.945, 4369.0, 66.0984
82.990752680, 60.945, 4533.0, 67.3276
83.055951320, 60.945, 4515.0, 67.1937
83.121149960, 60.945, 4400.0, 66.3325
83.186348600, 60.945, 4409.0, 66.4003
83.251547240, 60.945, 4536.0, 67.3498
83.316745880, 60.945, 4445.0, 66.6708
83.381944520, 60.945, 4408.0, 66.3928
83.447143160, 60.945, 4423.0, 66.5056
83.512341800, 60.945, 4464.0, 66.8132
83.577540440, 60.945, 4499.0, 67.0746
83.642739080, 60.945, 4513.0, 67.1789
83.707937720, 60.945, 4475.0, 66.8954
83.773136360, 60.945, 4299.0, 65.5668
83.838335000, 60.945, 4447.0, 66.6858
83.903533640, 60.945, 4495.0, 67.0448
83.968732280, 60.945, 4499.0, 67.0746
84.033930920, 60.945, 4443.0, 66.6558
84.099129560, 60.945, 4546.0, 67.4240
84.164328200, 60.945, 4533.0, 67.3276
84.229526840, 60.945, 4470.0, 66.8581
84.294725480, 60.945, 4420.0, 66.4831
84.359924120, 60.945, 4519.0, 67.2235
84.425122760, 60.945, 4376.0, 66.1513
84.490321400, 60.945, 4426.0, 66.5282
84.555520040, 60.945, 4374.0, 66.1362
84.620718680, 60.945, 4451.0, 66.7158
84.685917320, 60.945, 4528.0, 67.2904
84.751115960, 60.945, 4515.0, 67.1937
84.816314600, 60.945, 4351.0, 65.9621
84.881513240, 60.945, 4401.0, 66.3400
84.946711880, 60.945, 4565.0, 67.5648
85.011910520, 60.945, 4462.0, 66.7982
85.077109160, 60.945, 4478.0, 66.9179
85.142307800, 60.945, 4545.0, 67.4166
85.207506440, 60.945, 4453.0, 66.7308
85.272705080, 60.945, 4564.0, 67.5574
85.337903720, 60.945, 4521.0, 67.2384
85.403102360, 60.945, 4557.0, 67.5056
85.468301000, 60.945, 4491.0, 67.0149
85.533499640, 60.945, 4425.0, 66.5207
85.598698280, 60.945, 4624.0, 68.0000
85.663896920, 60.945, 4340.0, 65.8787
85.729095560, 60.945, 4519.0, 67.2235
85.794294200, 60.945, 4482.0, 66.9477
85.859492840, 60.945, 4663.0, 68.2862
85.924691480, 60.945, 4398.0, 66.3174
85.989890120, 60.945, 4473.0, 66.8805
86.055088760, 60.945, 4519.0, 67.2235
86.120287400, 60.945, 4431.0, 66.5658
86.185486040, 60.945, 4481.0, 66.9403
86.250684680, 60.945, 4380.0, 66.1816
86.315883320, 60.945, 4548.0, 67.4389
86.381081960, 60.945, 4531.0, 67.3127
86.446280600, 60.945, 4554.0, 67.4833
86.511479240, 60.945, 4573.0, 67.6240
86.576677880, 60.945, 4505.0, 67.1193
86.641876520, 60.945, 4463.0, 66.8057
86.707075160, 60.945, 4514.0, 67.1863
86.772273800, 60.945, 4477.0, 66.9104
86.837472440, 60.945, 4562.0, 67.5426
86.902671080, 60.945, 4423.0, 66.5056
86.967869720, 60.945, 4436.0, 66.6033
87.033068360, 60.945, 4526.0, 67.2756
87.098267000, 60.945, 4410.0, 66.4078
87.163465640, 60.945, 4472.0, 66.8730
87.228664280, 60.945, 4547.0, 67.4314
87.293862920, 60.945, 4419.0, 66.4756
87.359061560, 60.945, 4558.0, 67.5130
87.424260200, 60.945, 4587.0, 67.7274
87.489458840, 60.945, 4645.0, 68.1542
87.554657480, 60.945, 4574.0, 67.6314
87.619856120, 60.945, 4431.0, 66.5658
87.685054760, 60.945, 4438.0, 66.6183
87.750253400, 60.945, 4483.0, 66.9552
87.815452040, 60.945, 4456.0, 66.7533
87.880650680, 60.945, 4464.0, 66.8132
87.945849320, 60.945, 4551.0, 67.4611
88.011047960, 60.945, 4547.0, 67.4314
88.076246600, 60.945, 4587.0, 67.7274
88.141445240, 60.945, 4447.0, 66.6858
88.206643880, 60.945, 4561.0, 67.5352
88.271842520, 60.945, 4426.0, 66.5282
88.337041160, 60.945, 4495.0, 67.0448
88.402239800, 60.945, 4677.0, 68.3886
88.467438440, 60.945, 4484.0, 66.9627
88.532637080, 60.945, 4489.0, 67.0000
88.597835720, 60.945, 4467.0, 66.8356
88.663034360, 60.945, 4433.0, 66.5808
88.728233000, 60.945, 4567.0, 67.5796
88.793431640, 60.945, 4526.0, 67.2756
88.858630280, 60.945, 4565.0, 67.5648
88.923828920, 60.945, 4418.0, 66.4680
88.989027560, 60.945, 4483.0, 66.9552
89.054226200, 60.945, 4539.0, 67.3721
89.119424840, 60.945, 4474.0, 66.8880
89.184623480, 60.945, 4550.0, 67.4537
89.249822120, 60.945, 4519.0, 67.2235
89.315020760, 60.945, 4491.0, 67.0149
89.380219400, 60.945, 4649.0, 68.1836
89.445418040, 60.945, 4504.0, 67.1118
89.510616680, 60.945, 4460.0, 66.7832
89.575815320, 60.945, 4386.0, 66.2269
89.641013960, 60.945, 4493.0, 67.0298
89.706212600, 60.945, 4526.0, 67.2756
89.771411240, 60.945, 4554.0, 67.4833
89.836609880, 60.945, 4478.0, 66.9179
89.901808520, 60.945, 4492.0, 67.0224
89.967007160, 60.945, 4618.0, 67.9559
89.988740040, 60.945, 4445.0, 66.6708